<?xml version="1.0" encoding="UTF-8"?>
<testng-results skipped="0" failed="1" total="2" passed="1">
  <reporter-output>
  </reporter-output>
  <suite name="Default suite" duration-ms="144" started-at="2020-04-16T22:06:17Z" finished-at="2020-04-16T22:06:17Z">
    <groups>
    </groups>
    <test name="Default test" duration-ms="144" started-at="2020-04-16T22:06:17Z" finished-at="2020-04-16T22:06:17Z">
      <class name="Test.softAssert1">
        <test-method status="FAIL" signature="test1()[pri:0, instance:Test.softAssert1@18be83e4]" name="test1" duration-ms="43" started-at="2020-04-16T18:06:17Z" finished-at="2020-04-16T18:06:17Z">
          <exception class="java.lang.AssertionError">
            <message>
              <![CDATA[The following asserts failed:
	expected [true] but found [false],
	expected [false] but found [true],
	expected [Failed] but found [Sample]]]>
            </message>
            <full-stacktrace>
              <![CDATA[java.lang.AssertionError: The following asserts failed:
	expected [true] but found [false],
	expected [false] but found [true],
	expected [Failed] but found [Sample]
	at org.testng.asserts.SoftAssert.assertAll(SoftAssert.java:43)
	at Test.softAssert1.test1(softAssert1.java:20)
	at sun.reflect.NativeMethodAccessorImpl.invoke0(Native Method)
	at sun.reflect.NativeMethodAccessorImpl.invoke(Unknown Source)
	at sun.reflect.DelegatingMethodAccessorImpl.invoke(Unknown Source)
	at java.lang.reflect.Method.invoke(Unknown Source)
	at org.testng.internal.MethodInvocationHelper.invokeMethod(MethodInvocationHelper.java:86)
	at org.testng.internal.Invoker.invokeMethod(Invoker.java:643)
	at org.testng.internal.Invoker.invokeTestMethod(Invoker.java:820)
	at org.testng.internal.Invoker.invokeTestMethods(Invoker.java:1128)
	at org.testng.internal.TestMethodWorker.invokeTestMethods(TestMethodWorker.java:129)
	at org.testng.internal.TestMethodWorker.run(TestMethodWorker.java:112)
	at org.testng.TestRunner.privateRun(TestRunner.java:782)
	at org.testng.TestRunner.run(TestRunner.java:632)
	at org.testng.SuiteRunner.runTest(SuiteRunner.java:366)
	at org.testng.SuiteRunner.runSequentially(SuiteRunner.java:361)
	at org.testng.SuiteRunner.privateRun(SuiteRunner.java:319)
	at org.testng.SuiteRunner.run(SuiteRunner.java:268)
	at org.testng.SuiteRunnerWorker.runSuite(SuiteRunnerWorker.java:52)
	at org.testng.SuiteRunnerWorker.run(SuiteRunnerWorker.java:86)
	at org.testng.TestNG.runSuitesSequentially(TestNG.java:1244)
	at org.testng.TestNG.runSuitesLocally(TestNG.java:1169)
	at org.testng.TestNG.run(TestNG.java:1064)
	at org.testng.remote.AbstractRemoteTestNG.run(AbstractRemoteTestNG.java:115)
	at org.testng.remote.RemoteTestNG.initAndRun(RemoteTestNG.java:251)
	at org.testng.remote.RemoteTestNG.main(RemoteTestNG.java:77)
]]>
            </full-stacktrace>
          </exception> <!-- java.lang.AssertionError -->
          <reporter-output>
          </reporter-output>
        </test-method> <!-- test1 -->
        <test-method status="PASS" signature="test2()[pri:0, instance:Test.softAssert1@18be83e4]" name="test2" duration-ms="16" started-at="2020-04-16T18:06:17Z" finished-at="2020-04-16T18:06:17Z">
          <reporter-output>
          </reporter-output>
        </test-method> <!-- test2 -->
      </class> <!-- Test.softAssert1 -->
    </test> <!-- Default test -->
  </suite> <!-- Default suite -->
</testng-results>
